<robot name = "robot">
    <link name="0">
        <inertial>
            <origin xyz="0 0 2" rpy="0 0 0"/>
            <mass value="1" />
            <inertia ixx="100" ixy="0" ixz="0" iyy="100" iyz="0" izz="100" />
        </inertial>
        <visual>
            <origin xyz="0 0 2" rpy="0 0 0"/>
            <geometry>
                <box size="0.19015055933937663 0.7643455199323452 0.3656439028156777" />
            </geometry>
            <material name="Cyan">
                <color rgba="0 1.0 1.0 1.0"/>
            </material>
        </visual>
        <collision>
            <origin xyz="0 0 2" rpy="0 0 0"/>
            <geometry>
                <box size="0.19015055933937663 0.7643455199323452 0.3656439028156777" />
            </geometry>
        </collision>
    </link>
    <joint name="0_1" type="revolute">
       <parent link="0"/>
       <child  link="1"/>
       <origin rpy="0 0 0" xyz="0.0 0.0 1.966792409826962" />
     <axis xyz="1 0 0"/>
       <limit effort="0.0" lower="-3.14159" upper="3.14159" velocity="0.0"/>
    </joint>
    <link name="1">
        <inertial>
            <origin xyz="0.0 0.0 -0.2777257037235939" rpy="0 0 0"/>
            <mass value="1" />
            <inertia ixx="100" ixy="0" ixz="0" iyy="100" iyz="0" izz="100" />
        </inertial>
        <visual>
            <origin xyz="0.0 0.0 -0.2777257037235939" rpy="0 0 0"/>
            <geometry>
                <box size="0.5667312971732572 0.42271548482474053 0.5554514074471878" />
            </geometry>
            <material name="Green">
                <color rgba="0 1.0 0 1.0"/>
            </material>
        </visual>
        <collision>
            <origin xyz="0.0 0.0 -0.2777257037235939" rpy="0 0 0"/>
            <geometry>
                <box size="0.5667312971732572 0.42271548482474053 0.5554514074471878" />
            </geometry>
        </collision>
    </link>
    <joint name="1_2" type="revolute">
       <parent link="1"/>
       <child  link="2"/>
       <origin rpy="0 0 0" xyz="0.0 0.0 0.0" />
     <axis xyz="0 1 0"/>
       <limit effort="0.0" lower="-3.14159" upper="3.14159" velocity="0.0"/>
    </joint>
    <link name="2">
        <inertial>
            <origin xyz="0.0 0.0 0.4228511673807046" rpy="0 0 0"/>
            <mass value="1" />
            <inertia ixx="100" ixy="0" ixz="0" iyy="100" iyz="0" izz="100" />
        </inertial>
        <visual>
            <origin xyz="0.0 0.0 0.4228511673807046" rpy="0 0 0"/>
            <geometry>
                <box size="0.5551741268565132 0.449816093077936 0.8457023347614092" />
            </geometry>
            <material name="Cyan">
                <color rgba="0 1.0 1.0 1.0"/>
            </material>
        </visual>
        <collision>
            <origin xyz="0.0 0.0 0.4228511673807046" rpy="0 0 0"/>
            <geometry>
                <box size="0.5551741268565132 0.449816093077936 0.8457023347614092" />
            </geometry>
        </collision>
    </link>
    <joint name="2_3" type="revolute">
       <parent link="2"/>
       <child  link="3"/>
       <origin rpy="0 0 0" xyz="0.2775870634282566 0.0 0.4228511673807046" />
     <axis xyz="1 0 0"/>
       <limit effort="0.0" lower="-3.14159" upper="3.14159" velocity="0.0"/>
    </joint>
    <link name="3">
        <inertial>
            <origin xyz="0.33256417095870067 0.0 0.0" rpy="0 0 0"/>
            <mass value="1" />
            <inertia ixx="100" ixy="0" ixz="0" iyy="100" iyz="0" izz="100" />
        </inertial>
        <visual>
            <origin xyz="0.33256417095870067 0.0 0.0" rpy="0 0 0"/>
            <geometry>
                <box size="0.6651283419174013 0.6762577919750675 0.5839355444083707" />
            </geometry>
            <material name="Cyan">
                <color rgba="0 1.0 1.0 1.0"/>
            </material>
        </visual>
        <collision>
            <origin xyz="0.33256417095870067 0.0 0.0" rpy="0 0 0"/>
            <geometry>
                <box size="0.6651283419174013 0.6762577919750675 0.5839355444083707" />
            </geometry>
        </collision>
    </link>
</robot>