<robot name = "robot">
    <link name="0">
        <inertial>
            <origin xyz="0 0 2" rpy="0 0 0"/>
            <mass value="1" />
            <inertia ixx="100" ixy="0" ixz="0" iyy="100" iyz="0" izz="100" />
        </inertial>
        <visual>
            <origin xyz="0 0 2" rpy="0 0 0"/>
            <geometry>
                <box size="0.4809313380864627 0.8049812641094272 0.017764232457671114" />
            </geometry>
            <material name="Cyan">
                <color rgba="0 1.0 1.0 1.0"/>
            </material>
        </visual>
        <collision>
            <origin xyz="0 0 2" rpy="0 0 0"/>
            <geometry>
                <box size="0.4809313380864627 0.8049812641094272 0.017764232457671114" />
            </geometry>
        </collision>
    </link>
    <joint name="0_1" type="revolute">
       <parent link="0"/>
       <child  link="1"/>
       <origin rpy="0 0 0" xyz="0.0 0.0 1.7190822992257313" />
     <axis xyz="1 0 0"/>
       <limit effort="0.0" lower="-3.14159" upper="3.14159" velocity="0.0"/>
    </joint>
    <link name="1">
        <inertial>
            <origin xyz="0.0 0.0 -0.27152464188575326" rpy="0 0 0"/>
            <mass value="1" />
            <inertia ixx="100" ixy="0" ixz="0" iyy="100" iyz="0" izz="100" />
        </inertial>
        <visual>
            <origin xyz="0.0 0.0 -0.27152464188575326" rpy="0 0 0"/>
            <geometry>
                <box size="0.5432422259031231 0.9426915098712824 0.5430492837715065" />
            </geometry>
            <material name="Green">
                <color rgba="0 1.0 0 1.0"/>
            </material>
        </visual>
        <collision>
            <origin xyz="0.0 0.0 -0.27152464188575326" rpy="0 0 0"/>
            <geometry>
                <box size="0.5432422259031231 0.9426915098712824 0.5430492837715065" />
            </geometry>
        </collision>
    </link>
    <joint name="0_2" type="revolute">
       <parent link="0"/>
       <child  link="2"/>
       <origin rpy="0 0 0" xyz="0.0 -0.4558700741038584 2.0" />
     <axis xyz="1 0 0"/>
       <limit effort="0.0" lower="-3.14159" upper="3.14159" velocity="0.0"/>
    </joint>
    <link name="2">
        <inertial>
            <origin xyz="0.0 -0.47198213362466873 0.0" rpy="0 0 0"/>
            <mass value="1" />
            <inertia ixx="100" ixy="0" ixz="0" iyy="100" iyz="0" izz="100" />
        </inertial>
        <visual>
            <origin xyz="0.0 -0.47198213362466873 0.0" rpy="0 0 0"/>
            <geometry>
                <box size="0.4228872087737626 0.9439642672493375 0.9726379687240647" />
            </geometry>
            <material name="Cyan">
                <color rgba="0 1.0 1.0 1.0"/>
            </material>
        </visual>
        <collision>
            <origin xyz="0.0 -0.47198213362466873 0.0" rpy="0 0 0"/>
            <geometry>
                <box size="0.4228872087737626 0.9439642672493375 0.9726379687240647" />
            </geometry>
        </collision>
    </link>
</robot>